Workbook
Name liste: #REF!
Name liste: #REF!
Name liste: #REF!
Name liste: #REF!
Name liste: #REF!
Name Liste_caisses: '[1]LISTES POUR SIMULATEUR'!$L$14:$L$141
Name Liste_caisses: #REF!
Name Liste_caisses: #REF!
Name Liste_caisses: #REF!
Name Liste_caisses: #REF!
Name Liste_caisses: #REF!
Name Liste_communes: '[1]CODES COMMUNE & GRANDES VILLES'!$A$2:$A$5
Name Liste_communes: #REF!
Name Liste_communes: 'CODES COMMUNE & GRANDES VILLES'!$A$2:$A$5
Name liste_exos: '[1]LISTES POUR SIMULATEUR'!$A$28:$A$32
Name liste_exos: #REF!
Name liste_exos: #REF!
Name liste_exos: #REF!
Name liste_exos: #REF!
Name liste_exos: #REF!
Name Liste_motifs_exo: #REF!
Name Liste_motifs_exo: #REF!
Name Liste_motifs_exo: #REF!
Name Liste_motifs_exo: #REF!
Name Liste_motifs_exo: #REF!
Name Liste_nb_malades: '[1]LISTES POUR SIMULATEUR'!$L$2:$L$10
Name Liste_nb_malades: #REF!
Name Liste_nb_malades: #REF!
Name Liste_nb_malades: #REF!
Name Liste_nb_malades: #REF!
Name Liste_nb_malades: #REF!
Name Liste_prescripteur: #REF!
Name Liste_prescripteur: #REF!
Name Liste_prescripteur: #REF!
Name Liste_prescripteur: #REF!
Name Liste_prescripteur: #REF!
Name Liste_prescripteur: #REF!
Name Liste_prescripteur: #REF!
Name Liste_prescripteur: #REF!
Name Liste_prescripteur: #REF!
Name Liste_prescripteur: #REF!
Name Liste_prescripteur: #REF!
Name Liste_prescripteur: #REF!
Name Liste_prescripteur: #REF!
Name Liste_prescripteur: #REF!
Name Liste_prescripteur: #REF!
Name Liste_prescripteur: #REF!
Name Liste_prescripteur: #REF!
Name Liste_prescripteur: #REF!
Name Liste_prescripteur: #REF!
Name Liste_prescripteur: #REF!
Name Liste_prescripteur: #REF!
Name Liste_prescripteur: #REF!
Name Liste_prescripteur: #REF!
Name Liste_prescripteur: #REF!
Name Liste_prescripteur: #REF!
Name Liste_prescripteur: #REF!
Name Liste_prescripteur: #REF!
Name Liste_prescripteur: #REF!
Name Liste_prescripteur: #REF!

Sheet PREAMBULE
A1: DATE DE DERNIERE MISE A JOUR : 26/09/2025
A2: LE PRESENT FICHIER CONSTITUE L'ANNEXE 30 A LA NORME B2 POUR ILLUSTRER LES MODALITES DE FACTURATION EN NORME B2 VERS L'ASSURANCE MALADIE PAR LES SOCIETES DE TAXIS DANS LE CADRE DE LA NOUVELLE CONVENTION TAXIS 2025 - 2029 ET DU DECRET TIERS PAYANT CONTRE TRANSPORT PARTAGE CE DOCUMENT VIENT EN COMPLEMENT DU CAHIER DES CHARGES A L’ATTENTION DES EDITEURS DE LOGICIELS DE FACTURATION B2 TAXIS PUBLIE SUR AMELI.FR LES DONNEES ET VALEURS MENTIONNEES VISENT A ILLUSTRER LES MODALITES DE FACTURATION. IL CONVIENT DONC DE SE REFERER A LA CONVENTION ET A SES ANNEXES POUR DISPOSER DES VALEURS REELLES A APPLIQUER

Sheet Table matière
A1: PREAMBULE
A2: Table matière
A3: LISTE DES CAS ANNEXE 30
A4: CONVENTION CAS 1
A5: CONVENTION CAS 2
A6: CONVENTION CAS 3
A7: CONVENTION CAS 4
A8: CONVENTION CAS 5
A9: CONVENTION CAS 6
A10: CONVENTION CAS 7
A11: CONVENTION CAS 8
A12: CONVENTION CAS 9
... A42: B2 CODES ACTES TP TP

Sheet LISTE DES CAS ANNEXE 30
A1: SOCIETE DE TAXI DE N° AM : 422500009 SPECIALITE : 56 | D1: CARACTERISTIQUES PATIENT | I1: CARACTERISTIQUES FACTURE | K1: CARACTERISTIQUES TRAJETS
A2: N°CAS | B2: NOMBRE DE TRAJETS FACTURES | C2: TRAJET N° : | D2: NATURE D'ASSURANCE | E2: TAUX | F2: AME ? : O/N | G2: RLAM ? O/N | H2: C2S ? : O/N | I2: REFUS TRANSPORT PARTAGE | J2: TIERS PAYANT | K2: LIEU DEPART | L2: LIEU ARRIVEE | M2: DATE / HEURE DEPART | N2: DATE / HEURE ARRIVEE | O2: N° IMMATRICULATION VEHICULE | P2: COMMUNE D'ADS | Q2: DEPARTEMENT D'ADS | R2: ORGANISME LOCAL D'ADS | S2: DISTANCE PARCOURUE | T2: CONTEXTE : J, N , F | U2: NOMBRE DE MALADES | V2: SUPPLEMENT FORFAITAIRE ? : O / N | W2: PEAGES ? : O / N | X2: TPMR ? : O / N | Y2: TRAJET EN LIEN AVEC HOSPITALISATION ET RETOUR A VIDE ? : O/N | Z2: SI T PARTAGE : TRAJET SEUL > X KM ? : O/N
A3: CONVENTION CAS 1 | B3: 1 | C3: 1 | D3: MALADIE | E3: 0.55 | F3: NON | G3: NON | H3: NON | I3: Sans objet | J3: 05 - TP AMO SEUL | K3: 42-SAINT-ETIENNE | L3: 42-SAINT-ETIENNE | M3: 01/12/2025 à 10H00 | N3: 01/12/2025 à 10H11 | O3: AA-001-BB | P3: 42218 (SAINT-ETIENNE) | Q3: 042 | R3: 422 - CPAM DE LA LOIRE | S3: 3 | T3: JOUR | U3: 1 | V3: NON | W3: NON | X3: NON | Y3: NON | Z3: Sans objet
A5: CONVENTION CAS 2 | B5: 1 | C5: 1 | D5: MALADIE | E5: 0.55 | F5: NON | G5: NON | H5: NON | I5: Sans objet | J5: 05 - TP AMO SEUL | K5: 69-LYON | L5: 69-VILLEURBANNE | M5: 01/12/2025 à 10H00 | N5: 01/12/2025 à 10H11 | O5: EE-003-FF | P5: 69123 (LYON) | Q5: 069 | R5: 691 - CPAM DU RHONE | S5: 3 | T5: JOUR | U5: 1 | V5: NON | W5: NON | X5: NON | Y5: NON | Z5: Sans objet
A7: CONVENTION CAS 3 | B7: 1 | C7: 1 | D7: MALADIE | E7: 0.55 | F7: NON | G7: NON | H7: NON | I7: Sans objet | J7: 05 - TP AMO SEUL | K7: 69-LYON | L7: 42-SAINT-ETIENNE | M7: 01/12/2025 à 10H00 | N7: 01/12/2025 à 11h15 | O7: EE-003-FF | P7: 69123 (LYON) | Q7: 069 | R7: 691 - CPAM DU RHONE | S7: 63 | T7: JOUR | U7: 1 | V7: NON | W7: NON | X7: NON | Y7: NON | Z7: Sans objet
A9: CONVENTION CAS 4 | B9: 1 | C9: 1 | D9: MALADIE | E9: 0.55 | F9: NON | G9: NON | H9: NON | I9: Sans objet | J9: 05 - TP AMO SEUL | K9: 42-SAINT-ETIENNE | L9: 69-LYON | M9: 01/12/2025 à 10H00 | N9: 01/12/2025 à 11h15 | O9: AA-001-BB | P9: 42218 (SAINT-ETIENNE) | Q9: 042 | R9: 422 - CPAM DE LA LOIRE | S9: 63 | T9: JOUR | U9: 1 | V9: NON | W9: NON | X9: NON | Y9: OUI | Z9: Sans objet
A11: CONVENTION CAS 5 | B11: 1 | C11: 1 | D11: MALADIE | E11: 0.55 | F11: NON | G11: NON | H11: NON | I11: Sans objet | J11: 05 - TP AMO SEUL | K11: 42-SAINT-ETIENNE | L11: 42-MONTBRISON | M11: 01/12/2025 à 10H00 | N11: 01/12/2025 à 10h50 | O11: AA-001-BB | P11: 42218 (SAINT-ETIENNE) | Q11: 042 | R11: 422 - CPAM DE LA LOIRE | S11: 40 | T11: JOUR | U11: 1 | V11: OUI (TYPES 1 & 2) | W11: NON | X11: NON | Y11: NON | Z11: Sans objet
A13: CONVENTION CAS 6 | B13: 1 | C13: 1 | D13: MALADIE | E13: 0.55 | F13: NON | G13: NON | H13: NON | I13: Sans objet | J13: 05 - TP AMO SEUL | K13: 42-SAINT-ETIENNE | L13: 42-MONTBRISON | M13: 01/12/2025 à 10H00 | N13: 01/12/2025 à 10h40 | O13: AA-001-BB | P13: 42218 (SAINT-ETIENNE) | Q13: 042 | R13: 422 - CPAM DE LA LOIRE | S13: 43 | T13: JOUR | U13: 1 | V13: NON | W13: OUI (à 1,20€) | X13: NON | Y13: NON | Z13: Sans objet
A15: CONVENTION CAS 7 | B15: 2 | C15: 1 | D15: MALADIE | E15: 0.55 | F15: NON | G15: NON | H15: NON | I15: Sans objet | J15: 05 - TP AMO SEUL | K15: 42-SAINT-ETIENNE | L15: 42-MONTBRISON | M15: 01/12/2025 à 10H00 | N15: 01/12/2025 à 10h50 | O15: AA-001-BB | P15: 42218 (SAINT-ETIENNE) | Q15: 042 | R15: 422 - CPAM DE LA LOIRE | S15: 40 | T15: JOUR | U15: 1 | V15: NON | W15: NON | X15: OUI | Y15: NON | Z15: Sans objet
C16: 2 | D16: MALADIE | E16: 0.55 | F16: NON | G16: NON | H16: NON | I16: Sans objet | J16: 05 - TP AMO SEUL | K16: 42-MONTBRISON | L16: 42-SAINT-ETIENNE | M16: 01/12/2025 à 13H00 | N16: 01/12/2025 à 13h50 | O16: AA-001-BB | P16: 42218 (SAINT-ETIENNE) | Q16: 042 | R16: 422 - CPAM DE LA LOIRE | S16: 40 | T16: JOUR | U16: 1 | V16: NON | W16: NON | X16: OUI | Y16: NON | Z16: Sans objet
A18: CONVENTION CAS 8 | B18: 1 | C18: 1 | D18: MALADIE | E18: 0.55 | F18: NON | G18: NON | H18: NON | I18: Sans objet | J18: 05 - TP AMO SEUL | K18: 42-SAINT-ETIENNE | L18: 42-MONTBRISON | M18: 01/12/2025 à 20h00 | N18: 01/12/2025 à 20h40 | O18: AA-001-BB | P18: 42218 (SAINT-ETIENNE) | Q18: 042 | R18: 422 - CPAM DE LA LOIRE | S18: 43 | T18: NUIT | U18: 1 | V18: OUI (TYPES 1 & 2) | W18: OUI (à 1,20€) | X18: OUI | Y18: NON | Z18: Sans objet
A20: CONVENTION CAS 9 | B20: 1 | C20: 1 | D20: MALADIE | E20: 0.55 | F20: NON | G20: NON | H20: NON | I20: Sans objet | J20: 05 - TP AMO SEUL | K20: 42-SAINT-ETIENNE | L20: 42-MONTBRISON | M20: 11/11/2025 à 10h00 | N20: 11/11/10/2025 à 10h40 | O20: AA-001-BB | P20: 42218 (SAINT-ETIENNE) | Q20: 042 | R20: 422 - CPAM DE LA LOIRE | S20: 43 | T20: DIM / J FERIE | U20: 1 | V20: OUI (TYPES 1 & 2) | W20: OUI (à 1,20€) | X20: OUI | Y20: OUI | Z20: Sans objet
A22: CONVENTION CAS 10 | B22: 1 | C22: 1 | D22: MALADIE | E22: 0.55 | F22: NON | G22: NON | H22: NON | I22: NON | J22: 05 - TP AMO SEUL | K22: 42-SAINT-ETIENNE | L22: 42-MONTBRISON | M22: 01/12/2025 à 10H00 | N22: 01/12/2025 à 10h40 | O22: AA-001-BB | P22: 42218 (SAINT-ETIENNE) | Q22: 042 | R22: 422 - CPAM DE LA LOIRE | S22: 43 | T22: JOUR | U22: 2 | V22: OUI (TYPE 1) | W22: OUI (à 0,60€) | X22: OUI | Y22: NON | Z22: NON
A24: CONVENTION CAS 11 | B24: 1 | C24: 1 | D24: MALADIE | E24: 0.55 | F24: NON | G24: NON | H24: NON | I24: NON | J24: 05 - TP AMO SEUL | K24: 69-LYON | L24: 42-SAINT-ETIENNE | M24: 01/12/2025 à 10H00 | N24: 01/12/2025 à 11h15 | O24: EE-003-FF | P24: 69123 (LYON) | Q24: 069 | R24: 691 - CPAM DU RHONE | S24: 63 | T24: JOUR | U24: 4 | V24: OUI (TYPE 1) | W24: NON | X24: OUI | Y24: OUI | Z24: NON
A26: CONVENTION CAS 12 | B26: 1 | C26: 1 | D26: MALADIE | E26: 0.55 | F26: NON | G26: NON | H26: NON | I26: NON | J26: 05 - TP AMO SEUL | K26: 42-SAINT-ETIENNE | L26: 42-MONTBRISON | M26: 01/12/2025 à 10H00 | N26: 01/12/2025 à 10h40 | O26: AA-001-BB | P26: 42218 (SAINT-ETIENNE) | Q26: 042 | R26: 422 - CPAM DE LA LOIRE | S26: 43 | T26: JOUR | U26: 3 | V26: OUI (TYPE 1) | W26: OUI (à 0,40€) | X26: OUI | Y26: NON | Z26: OUI
A28: CONVENTION CAS 13 | B28: 1 | C28: 1 | D28: MALADIE | E28: 0.55 | F28: NON | G28: NON | H28: NON | I28: NON | J28: 05 - TP AMO SEUL | K28: 42-SAINT-ETIENNE | L28: 42-MONTBRISON | M28: 01/12/2025 à 20h00 | N28: 01/12/2025 à 20h40 | O28: AA-001-BB | P28: 42218 (SAINT-ETIENNE) | Q28: 042 | R28: 422 - CPAM DE LA LOIRE | S28: 43 | T28: NUIT | U28: 3 | V28: OUI (TYPE 1) | W28: OUI (à 0,40€) | X28: OUI | Y28: OUI | Z28: NON
A30: CONVENTION CAS 14 | B30: 1 | C30: 1 | D30: MALADIE | E30: 0.55 | F30: NON | G30: NON | H30: NON | I30: NON | J30: 05 - TP AMO SEUL | K30: 69-LYON | L30: 42-SAINT-ETIENNE | M30: 11/11/2025 à 10H00 | N30: 11/11/2025 à 11h15 | O30: EE-003-FF | P30: 69123 (LYON) | Q30: 069 | R30: 691 - CPAM DU RHONE | S30: 63 | T30: DIM / J FERIE | U30: 4 | V30: OUI (TYPE 1) | W30: NON | X30: OUI | Y30: OUI | Z30: OUI
A32: CONVENTION CAS 15 | B32: 3 | C32: 1 | D32: MALADIE | E32: 0.55 | F32: NON | G32: NON | H32: OUI | I32: Sans objet | J32: 15 - TP AMO & TP AMC | K32: 42-SAINT-ETIENNE | L32: 42-MONTBRISON | M32: 01/12/2025 à 10H00 | N32: 01/12/2025 à 10h50 | O32: AA-001-BB | P32: 42218 (SAINT-ETIENNE) | Q32: 042 | R32: 422 - CPAM DE LA LOIRE | S32: 40 | T32: JOUR | U32: 1 | V32: OUI (TYPES 1 & 2) | W32: NON | X32: OUI | Y32: NON | Z32: Sans objet
C33: 2 | D33: MALADIE | E33: 0.55 | F33: NON | G33: NON | H33: OUI | I33: NON | K33: 42-MONTBRISON | L33: 42-SAINT-ETIENNE | M33: 01/12/2025 à 20H00 | N33: 01/12/2025 à 20h50 | O33: AA-001-BB | P33: 42218 (SAINT-ETIENNE) | Q33: 042 | R33: 422 - CPAM DE LA LOIRE | S33: 40 | T33: NUIT | U33: 3 | V33: OUI (TYPES 1 & 2) | W33: NON | X33: OUI | Y33: NON | Z33: NON
C34: 3 | D34: MALADIE | E34: 0.55 | F34: NON | G34: NON | H34: OUI | I34: NON | K34: 42-SAINT-ETIENNE | L34: 42-MONTBRISON | M34: 25/12/2025 à 10H00 | N34: 25/12/2025 à 10h50 | O34: AA-001-BB | P34: 42218 (SAINT-ETIENNE) | Q34: 042 | R34: 422 - CPAM DE LA LOIRE | S34: 40 | T34: DIM / J FERIE | U34: 4 | V34: OUI (TYPE 1) | W34: NON | X34: OUI | Y34: OUI | Z34: NON
A36: CONVENTION CAS 16 | B36: 5 | C36: 1 | D36: MATERNITE | E36: 1 | F36: NON | G36: NON | H36: NON | I36: NON | J36: 05 - TP AMO SEUL | K36: 69-LYON | L36: 42-SAINT-ETIENNE | M36: 10/11/2025 à 10H00 | N36: 10/11/2025 à 11h15 | O36: EE-003-FF | P36: 69123 (LYON) | Q36: 069 | R36: 691 - CPAM DU RHONE | S36: 63 | T36: JOUR | U36: 2 | V36: OUI (TYPE 1) | W36: NON | X36: NON | Y36: NON | Z36: OUI
C37: 2 | D37: MATERNITE | E37: 1 | F37: NON | G37: NON | H37: NON | I37: NON | K37: 42-SAINT-ETIENNE | L37: 69-LYON | M37: 11/11/2025 à 11h00 | N37: 11/11/2025 à 12h15 | O37: AA-001-BB | P37: 42218 (SAINT-ETIENNE) | Q37: 042 | R37: 422 - CPAM DE LA LOIRE | S37: 63 | T37: DIM / J FERIE | U37: 2 | V37: OUI (TYPES 1 & 2 & 3) | W37: NON | X37: NON | Y37: NON | Z37: NON
C38: 3 | D38: MATERNITE | E38: 1 | F38: NON | G38: NON | H38: NON | I38: NON | K38: 69-LYON | L38: 42-SAINT-ETIENNE | M38: 25/12/2025 à 10H00 | N38: 25/12/2025 à 11h15 | O38: EE-003-FF | P38: 69123 (LYON) | Q38: 069 | R38: 691 - CPAM DU RHONE | S38: 63 | T38: DIM / J FERIE | U38: 2 | V38: OUI (TYPE 1) | W38: NON | X38: NON | Y38: OUI | Z38: NON
C39: 4 | D39: MATERNITE | E39: 1 | F39: NON | G39: NON | H39: NON | I39: NON | K39: 42-SAINT-ETIENNE | L39: 69-LYON | M39: 26/12/2025 à 09H00 | N39: 26/12/2025 à 10H15 | O39: AA-001-BB | P39: 42218 (SAINT-ETIENNE) | Q39: 042 | R39: 422 - CPAM DE LA LOIRE | S39: 63 | T39: JOUR | U39: 4 | V39: OUI (TYPE 2) | W39: NON | X39: NON | Y39: NON | Z39: OUI
C40: 5 | D40: MATERNITE | E40: 1 | F40: NON | G40: NON | H40: NON | I40: Sans objet | K40: 69-LYON | L40: 42-SAINT-ETIENNE | M40: 27/12/2025 à 20h00 | N40: 27/12/2025 à 21h15 | O40: EE-003-FF | P40: 69123 (LYON) | Q40: 069 | R40: 691 - CPAM DU RHONE | S40: 63 | T40: NUIT | U40: 1 | V40: OUI (TYPE 1) | W40: NON | X40: NON | Y40: OUI | Z40: Sans objet
A42: CONVENTION CAS 17 | B42: 4 | C42: 1 | D42: MALADIE | E42: 0.55 | F42: NON | G42: NON | H42: OUI | I42: so | J42: 15 - TP AMO & TP AMC | K42: 69-LYON | L42: 42-SAINT-ETIENNE | M42: Samedi 06/12/2025 à 19h00 | N42: Samedi 06/12/2025 à 20h15 | O42: EE-003-FF | P42: 69123 (LYON) | Q42: 069 | R42: 691 - CPAM DU RHONE | S42: 63 | T42: DIM / J FERIE | U42: 1 | V42: NON | W42: NON | X42: NON | Y42: NON | Z42: Sans objet
B43: 4 | C43: 2 | D43: MALADIE | E43: 0.55 | F43: NON | G43: NON | H43: OUI | I43: so | K43: 69-LYON | L43: 42-SAINT-ETIENNE | M43: Samedi 13/12/2025 à 19h30 | N43: Samedi 13/12/2025 à 20h45 | O43: EE-003-FF | P43: 69123 (LYON) | Q43: 069 | R43: 691 - CPAM DU RHONE | S43: 63 | T43: NUIT | U43: 1 | V43: NON | W43: NON | X43: NON | Y43: NON | Z43: Sans objet
B44: 4 | C44: 3 | D44: MALADIE | E44: 0.55 | F44: NON | G44: NON | H44: OUI | I44: so | K44: 69-LYON | L44: 42-SAINT-ETIENNE | M44: Dimanche 21/12/2025 à 7h00 | N44: Dimanche 21/12/2025 à 8h15 | O44: EE-003-FF | P44: 69123 (LYON) | Q44: 069 | R44: 691 - CPAM DU RHONE | S44: 63 | T44: NUIT | U44: 1 | V44: NON | W44: NON | X44: NON | Y44: NON | Z44: Sans objet
B45: 4 | C45: 4 | D45: MALADIE | E45: 0.55 | F45: NON | G45: NON | H45: OUI | I45: so | K45: 69-LYON | L45: 42-SAINT-ETIENNE | M45: Dimanche 28/12/2025 à 7h30 | N45: Dimanche 28/12/2025 à 8h45 | O45: EE-003-FF | P45: 69123 (LYON) | Q45: 069 | R45: 691 - CPAM DU RHONE | S45: 63 | T45: DIM / J FERIE | U45: 1 | V45: NON | W45: NON | X45: NON | Y45: NON | Z45: Sans objet
A47: CONVENTION CAS 18 | B47: 1 | C47: 1 | D47: MALADIE RLAM | E47: 1 | F47: NON | G47: OUI | H47: NON | I47: Sans objet | J47: 05 - TP AMO SEUL | K47: 69-LYON | L47: 42-SAINT-ETIENNE | M47: 01/12/2025 à 10H00 | N47: 01/12/2025 à 11h15 | O47: EE-003-FF | P47: 69123 (LYON) | Q47: 069 | R47: 691 - CPAM DU RHONE | S47: 63 | T47: JOUR | U47: 1 | V47: NON | W47: NON | X47: NON | Y47: NON | Z47: Sans objet
A49: CONVENTION CAS 19 | B49: 1 | C49: 1 | D49: MALADIE | E49: 0 | F49: OUI | G49: NON | H49: NON | I49: Sans objet | J49: 15 - TP AMO & TP AMC | K49: 69-LYON | L49: 42-SAINT-ETIENNE | M49: 01/12/2025 à 10H00 | N49: 01/12/2025 à 11h15 | O49: EE-003-FF | P49: 69123 (LYON) | Q49: 069 | R49: 691 - CPAM DU RHONE | S49: 63 | T49: JOUR | U49: 1 | V49: NON | W49: NON | X49: NON | Y49: NON | Z49: Sans objet
A51: CONVENTION CAS 20 | B51: 5 | C51: 1 | D51: AT / MP | E51: 1 | F51: NON | G51: NON | H51: NON | I51: NON | J51: 05 - TP AMO SEUL | K51: 69-LYON | L51: 42-SAINT-ETIENNE | M51: 10/11/2025 à 10H00 | N51: 10/11/2025 à 11h15 | O51: EE-003-FF | P51: 69123 (LYON) | Q51: 069 | R51: 691 - CPAM DU RHONE | S51: 63 | T51: JOUR | U51: 2 | V51: OUI (TYPE 1) | W51: NON | X51: NON | Y51: NON | Z51: OUI
C52: 2 | D52: AT / MP | E52: 1 | F52: NON | G52: NON | H52: NON | I52: NON | K52: 42-SAINT-ETIENNE | L52: 69-LYON | M52: 11/11/2025 à 11h00 | N52: 11/11/2025 à 12h15 | O52: AA-001-BB | P52: 42218 (SAINT-ETIENNE) | Q52: 042 | R52: 422 - CPAM DE LA LOIRE | S52: 63 | T52: DIM / J FERIE | U52: 2 | V52: OUI (TYPES 1 & 2 & 3) | W52: NON | X52: NON | Y52: NON | Z52: NON
C53: 3 | D53: AT / MP | E53: 1 | F53: NON | G53: NON | H53: NON | I53: NON | K53: 69-LYON | L53: 42-SAINT-ETIENNE | M53: 25/12/2025 à 10H00 | N53: 25/12/2025 à 11h15 | O53: EE-003-FF | P53: 69123 (LYON) | Q53: 069 | R53: 691 - CPAM DU RHONE | S53: 63 | T53: DIM / J FERIE | U53: 2 | V53: OUI (TYPE 1) | W53: NON | X53: NON | Y53: OUI | Z53: NON
C54: 4 | D54: AT / MP | E54: 1 | F54: NON | G54: NON | H54: NON | I54: NON | K54: 42-SAINT-ETIENNE | L54: 69-LYON | M54: 26/12/2025 à 09H00 | N54: 26/12/2025 à 10H15 | O54: AA-001-BB | P54: 42218 (SAINT-ETIENNE) | Q54: 042 | R54: 422 - CPAM DE LA LOIRE | S54: 63 | T54: JOUR | U54: 4 | V54: OUI (TYPE 2) | W54: NON | X54: NON | Y54: NON | Z54: OUI
C55: 5 | D55: AT / MP | E55: 1 | F55: NON | G55: NON | H55: NON | I55: Sans objet | K55: 69-LYON | L55: 42-SAINT-ETIENNE | M55: 27/12/2025 à 20h00 | N55: 27/12/2025 à 21h15 | O55: EE-003-FF | P55: 69123 (LYON) | Q55: 069 | R55: 691 - CPAM DU RHONE | S55: 63 | T55: NUIT | U55: 1 | V55: OUI (TYPE 1) | W55: NON | X55: NON | Y55: OUI | Z55: Sans objet
A57: TP CONTRE TP CAS 1 | B57: 1 | C57: 1 | D57: MALADIE | E57: 0.55 | F57: NON | G57: NON | H57: NON | I57: OUI | J57: 00 - HTP | K57: 69-LYON | L57: 42-SAINT-ETIENNE | M57: 01/12/2025 à 10H00 | N57: 01/12/2025 à 11H15 | O57: EE-003-FF | P57: 69123 (LYON) | Q57: 069 | R57: 691 - CPAM DU RHONE | S57: 63 | T57: JOUR | U57: 1 | V57: NON | W57: NON | X57: NON | Y57: NON | Z57: Sans objet
A59: TP CONTRE TP CAS 2 | B59: 1 | C59: 1 | D59: MALADIE | E59: 0.55 | F59: NON | G59: NON | H59: NON | I59: OUI | J59: 00 - HTP | K59: 42-SAINT-ETIENNE | L59: 69-LYON | M59: 01/12/2025 à 20H00 | N59: 01/12/2025 à 21H15 | O59: AA-001-BB | P59: 42218 (SAINT-ETIENNE) | Q59: 042 | R59: 422 - CPAM DE LA LOIRE | S59: 63 | T59: NUIT | U59: 1 | V59: OUI (TYPE 1) | W59: NON | X59: OUI | Y59: OUI | Z59: Sans objet
A61: TP CONTRE TP CAS 3 | B61: 2 | C61: 1 | D61: MALADIE | E61: 0.55 | F61: NON | G61: NON | H61: NON | I61: OUI | J61: 00 - HTP | K61: 69-LYON | L61: 42-SAINT-ETIENNE | M61: 10/11/2025 à 20H00 | N61: 10/11/2025 à 21H15 | O61: EE-003-FF | P61: 69123 (LYON) | Q61: 069 | R61: 691 - CPAM DU RHONE | S61: 63 | T61: NUIT | U61: 1 | V61: OUI (TYPE 1) | W61: NON | X61: OUI | Y61: OUI | Z61: Sans objet
C62: 2 | D62: MALADIE | E62: 0.55 | F62: NON | G62: NON | H62: NON | I62: OUI | J62: 00 - HTP | K62: 69-LYON | L62: 42-SAINT-ETIENNE | M62: 11/11/2025 à 16H00 | N62: 11/11/2025 à 17H15 | O62: EE-003-FF | P62: 69123 (LYON) | Q62: 069 | R62: 691 - CPAM DU RHONE | S62: 63 | T62: DIM / J FERIE | U62: 1 | V62: NON | W62: NON | X62: OUI | Y62: NON | Z62: Sans objet
...

Sheet CONVENTION CAS 1
A1: Table des matières | B1: CARACTERISTIQUES METIERS DU OU DES TRAJETS FACTURES
A3: SOCIETE DE TAXI DE N° AM : 422500009 SPECIALITE : 56 | D3: CARACTERISTIQUE PATIENT | G3: CARACTERISTIQUES FACTURE | I3: CARACTERISTIQUES TRAJETS | Z3: ASSURE | AG3: PRESCRIPTEUR
A4: N°CAS | B4: NOMBRE DE TRAJETS FACTURES | C4: TRAJET N° : | D4: NATURE D'ASSURANCE | E4: TAUX | F4: C2S ? : O/N | G4: REFUS TRANSPORT PARTAGE | H4: TIERS PAYANT | I4: LIEU DEPART | J4: LIEU ARRIVEE | K4: DATE / HEURE DEPART | L4: DATE / HEURE ARRIVEE | M4: N° IMMATRICULATION VEHICULE | N4: COMMUNE D'ADS | O4: DEPARTEMENT D'ADS | P4: ORGANISME LOCAL D'ADS | Q4: DISTANCE PARCOURUE | R4: CONTEXTE : J, N , F | S4: NOMBRE DE MALADES | T4: SUPPLEMENT FORFAITAIRE ? : O / N | U4: PEAGES ? : O / N | V4: TPMR ? : O / N | W4: TRAJET EN LIEN AVEC HOSPITALISATION ET RETOUR A VIDE ? : O/N | X4: SI T PARTAGE : TRAJET SEUL > X KM ? : O/N | Z4: NIR | AA4: DATE DE NAISSANCE | AB4: RANG | AC4: REGIME | AD4: CAISSE | AE4: CENTRE | AG4: N°AM | AH4: SPECIALITE | AI4: NN°RPPS
A5: ='LISTE DES CAS ANNEXE 30'!A3 -> CONVENTION CAS 1 | B5: ='LISTE DES CAS ANNEXE 30'!B3 -> 1 | C5: ='LISTE DES CAS ANNEXE 30'!C3 -> 1 | D5: ='LISTE DES CAS ANNEXE 30'!D3 -> MALADIE | E5: ='LISTE DES CAS ANNEXE 30'!E3 -> 0.55 | F5: ='LISTE DES CAS ANNEXE 30'!H3 -> NON | G5: ='LISTE DES CAS ANNEXE 30'!I3 -> Sans objet | H5: ='LISTE DES CAS ANNEXE 30'!J3 -> 05 - TP AMO SEUL | I5: ='LISTE DES CAS ANNEXE 30'!K3 -> 42-SAINT-ETIENNE | J5: ='LISTE DES CAS ANNEXE 30'!L3 -> 42-SAINT-ETIENNE | K5: ='LISTE DES CAS ANNEXE 30'!M3 -> 01/12/2025 à 10H00 | L5: ='LISTE DES CAS ANNEXE 30'!N3 -> 01/12/2025 à 10H11 | M5: ='LISTE DES CAS ANNEXE 30'!O3 -> AA-001-BB | ... X5: ='LISTE DES CAS ANNEXE 30'!Z3 -> Sans objet | Z5: 1500101001001 | AA5: 500101 | AB5: 1 | AC5: 01 | AD5: 422 | AE5: 0000 | AG5: 421000001 | AH5: 01 | AI5: 11111110118
A7: FACTURE B2 CORRESPONDANT
A9: TYPE 000 DEBUT FICHIER | B9: Type d’enregistrement | C9: Type d’émetteur | D9: Numéro d’émetteur | E9: FILLER | F9: Type de destinataire | G9: N° de destinataire | H9: Date de réception du flux sur le frontal | I9: Application | J9: Identification du fichier | K9: Date de création du fichier | L9: Norme | M9: Version de Norme | N9: FILLER | O9: FILLER | P9: FILLER | Q9: FILLER | R9: Longueur d’enregistrement | S9: FILLER | T9: Zone message
B10: 1-3 | C10: 4-5 | D10: 6-19 | E10: 20-25 | F10: 26-27 | G10: 28-41 | H10: 42-47 | I10: 48-49 | J10: 50-55 | K10: 56-61 | L10: 62-65 | M10: 66-67 | N10: 68 | O10: 69 | P10: 70-72 | Q10: 73-82 | R10: 83-85 | S10: 86-91 | T10: 92-128
B11: 3 | C11: 2 | D11: 14 | E11: 6 | F11: 2 | G11: 14 | H11: 6 | I11: 2 | J11: 6 | K11: 6 | L11: 4 | M11: 2 | N11: 1 | O11: 1 | P11: 3 | Q11: 10 | R11: 3 | S11: 6 | T11: 37
B12: N | C12: A | D12: N | E12: A | F12: A | G12: N | H12: A | I12: A | J12: A | K12: N | L12: A | M12: A | N12: A | O12: A | P12: A | Q12: A | R12: N | S12: A | T12: N
B13: O | C13: O | D13: O | E13: F | F13: O | G13: O | H13: O | I13: O | J13: O | K13: O | L13: O | M13: O | N13: F | O13: F | P13: F | Q13: F | R13: F | S13: F | T13: O
B14: 000 | C14: TP | D14: 00000422500009 | F14: CT | G14: 00000001000422 | H14: 251231 | I14: TR | J14: TESTB2 | K14: 251231 | L14: TA | M14: B2 | R14: 128
A16: TYPE 1 DEBUT LOT | B16: Type d’enregistrement | C16: N° partenaire de santé + clé | D16: Origine du fichier | E16: N° d’organisme destinataire | F16: N° de lot | G16: Catégorie | H16: Statut juridique | I16: Mode de fixation des tarifs | J16: Nom ou raison sociale du partenaire de santé | K16: Version de norme utilisée | L16: Date de création du lot | M16: Filler | N16: Code norme | O16: Top certification du lot | P16: Numéro de version de norme | Q16: Unité monétaire de facturation | R16: Grand régime de la caisse pivot ou de la caisse de paiement unique privés, ou pour les établissements publics et privés antérieurement sous DG | S16: N° de la caisse pivot ou de la caisse de paiement unique | T16: Indication de dispositif Caisse Centralisatrice des Paiements ou de dispositif Caisse de Paiement Unique | U16: FILLER
B17: 1 | C17: 2-10 | D17: 11-16 | E17: 17-19 | F17: 20-22 | G17: 23-25 | H17: 26-27 | I17: 28-29 | J17: 30-69 | K17: 70-71 | L17: 72-77 | M17: 78 | N17: 79-80 | O17: 81 | P17: 82-87 | Q17: 88 | R17: 89-90 | S17: 91-93 | T17: 94 | U17: 95-128
B18: 1 | C18: 9 | D18: 6 | E18: 3 | F18: 3 | G18: 3 | H18: 2 | I18: 2 | J18: 40 | K18: 2 | L18: 6 | M18: 1 | N18: 2 | O18: 1 | P18: 6 | Q18: 1 | R18: 2 | S18: 3 | T18: 1 | U18: 34
B19: N | C19: N | D19: A | E19: N | F19: N | G19: A | H19: A | I19: A | J19: A | K19: A | L19: N | M19: A | N19: A | O19: A | P19: N | Q19: A | R19: A | S19: A | T19: N | U19: A
B20: O | C20: O | D20: F | E20: O | F20: O | G20: F | H20: F | I20: F | J20: O | K20: O | L20: O | M20: F | N20: O | O20: F | P20: O | Q20: F | R20: F | S20: F | T20: F | U20: FILLER
B21: 1 | C21: 422500009 | E21: 422 | F21: 001 | J21: SIMULATEUR B2 NOUVELLE CONVENTION TAXI | K21: B2 | L21: 251231 | N21: TA | P21: 062007 | Q21: U
A23: TYPE 2 DEBUT FACTURE | B23: Type d’enregistrement | C23: N° partenaire de santé + clé | D23: FILLER | E23: N° immatriculation assuré | F23: Clé N° immatriculation | G23: N° facture | H23: Complément du type | I23: Marquage de la facture | J23: Indicateur de forçage de la tarification de la part AMO | K23: Nature d’opération | L23: Date de facturation | M23: Top éclatement des flux par le PS | N23: Type de facture | O23: Facture sécurisée sur un dispositif portable | P23: Code Grand Régime | Q23: N° Caisse gestionnaire | R23: N° Centre gestionnaire | S23: Nature de la pièce justificative des droits | T23: N° prescripteur + clé | U23: Date de prescription | V23: Régime de prestation de l’assuré | W23: Nature d’assurance | X23: Justification d’exonération ou de modulation du ticket modérateur | Y23: Date Maternité | Z23: Numéro accident du travail ou date d’accident de droit commun | AA23: Présence d’une CPS de remplaçant pour sécurisation de la facture | AB23: Date de naissance du bénéficiaire | AC23: Rang de naissance | AD23: Rang de bénéficiaire | AE23: N° d’adhérent | AF23: Spécialité de prescripteur | AG23: Destinataire du règlement | AH23: Type de contrat souscrit auprès d’un organisme complémentaire | AI23: N° d’organisme complémentaire
B24: 1 | C24: 2-10 | D24: 11 | E24: 12-24 | F24: 25-26 | G24: 27-35 | H24: 36 | I24: 37 | J24: 38 | K24: 39 | L24: 40-45 | M24: 46 | N24: 47 | O24: 48 | P24: 49-50 | Q24: 51-53 | R24: 54-57 | S24: 58 | T24: 59-67 | U24: 68-73 | V24: 74-76 | W24: 77-78 | X24: 79 | Y24: 80-85 | Z24: 86-94 | AA24: 95 | AB24: 96-101 | AC24: 102 | AD24: 103-104 | AE24: 105-112 | AF24: 113-114 | AG24: 115-116 | AH24: 117-118 | AI24: 119-128
B25: 1 | C25: 9 | D25: 1 | E25: 13 | F25: 2 | G25: 9 | H25: 1 | I25: 1 | J25: 1 | K25: 1 | L25: 6 | M25: 1 | N25: 1 | O25: 1 | P25: 2 | Q25: 3 | R25: 4 | S25: 1 | T25: 9 | U25: 6 | V25: 3 | W25: 2 | X25: 1 | Y25: 6 | Z25: 9 | AA25: 1 | AB25: 6 | AC25: 1 | AD25: 2 | AE25: 8 | AF25: 2 | AG25: 2 | AH25: 2 | AI25: 10
B26: N | C26: N | D26: A | E26: A | F26: N | G26: N | H26: A | I26: A | J26: A | K26: N | L26: N | M26: A | N26: A | O26: A | P26: N | Q26: N | R26: N | S26: N | T26: N | U26: N | V26: A | W26: N | X26: A | Y26: N | Z26: N | AA26: A | AB26: N | AC26: N | AD26: A | AE26: A | AF26: N | AG26: N | AH26: N | AI26: A
B27: O | C27: O | D27: F | E27: O | F27: O | G27: O | H27: F | I27: F | J27: F | K27: O | L27: O | M27: F | N27: F | O27: F | P27: O | Q27: O | R27: O | S27: O | T27: O | U27: O | V27: F | W27: F | X27: O | Y27: F | Z27: F | AA27: O | AB27: O | AC27: F | AD27: F | AE27: F | AF27: F | AG27: F | AH27: F | AI27: F
B28: 2 | C28: 422500009 | E28: 1500101001001 | F28: 77 | G28: 250000001 | H28: A | K28: 1 | L28: 251231 | P28: 01 | Q28: 422 | R28: 0000 | S28: 2 | T28: 421000001 | U28: 250701 | W28: 10 | X28: 0 | Y28: 000000 | Z28: 000000000 | AB28: 500101 | AC28: 1 | AF28: 01 | AG28: 05 | AH28: 00
A30: TYPE 2E RPPS PRESCRIPTEUR | B30: Type d’enregistrement | C30: N° partenaire de santé + clé | D30: FILLER | E30: N° immatriculation assuré | F30: Clé N° immatriculation | G30: N° de facture | H30: Complément de type | I30: Identfifiant RPPS du prescripteur | J30: N° de la structure dans laquelle le PS a exécuté l’acte | K30: FILLER
B31: 1 | C31: 2-10 | D31: 11 | E31: 12-24 | F31: 25-26 | G31: 27-35 | H31: 36 | I31: 37-47 | J31: 48-61 | K31: 62-128
B32: 1 | C32: 9 | D32: 1 | E32: 13 | F32: 2 | G32: 9 | H32: 1 | I32: 11 | J32: 14 | K32: 67
B33: N | C33: N | D33: A | E33: A | F33: N | G33: N | H33: A | I33: N | J33: N | K33: A
B34: O | C34: O | D34: F | E34: O | F34: O | G34: O | H34: F | I34: F | J34: F | K34: F
B35: 2 | C35: 422500009 | E35: 1500101001001 | F35: 77 | G35: 250000001 | H35: E | I35: 11111110118 | AG35: LIGNE A GENERER
A37: TYPE 4A COMPOSANTE FORFAIT | B37: Type d’enregistrement | C37: N° partenaire de santé + clé | D37: FILLER | E37: N° immatriculation assuré | F37: Clé N° immatriculation | G37: N° de facture | H37: Complément de type | I37: Séquence | J37: Mode de traitement | K37: Discipline de prestations (ex DMT) | L37: Date de la demande d’accord préalable ou date d’accord de prise en charge CMU. | M37: Code accord préalable | N37: Séquence de renouvellement | O37: Code Participation assuré | P37: Justification d’exonération du Ticket Modérateur au niveau de l’acte | Q37: N° exécutant + clé ayant effectué l’acte ou fourni le produit | R37: Zone tarif de l’exécutant | S37: Spécialité de l’exécutant | T37: Date de l’acte, de la délivrance du produit | U37: Code acte | V37: Quantité d'actes | W37: Coefficient | X37: Dénombrement | Y37: Prix unitaire | Z37: Base de remboursement | AA37: Taux applicable à la prestation- | AB37: Montant remboursable par l’organisme d’Assurance Maladie Obligatoire | AC37: Montant des honoraires ou de la dépense (dépassement compris ou après remise pour la norme FR) | AD37: Qualificatif de la dépense | AE37: Code lieu | AF37: Montant remboursable par l’organisme complémentaire
B38: 1 | C38: 2-10 | D38: 11 | E38: 12-24 | F38: 25-26 | G38: 27-35 | H38: 36 | I38: 37-38 | J38: 39-40 | K38: 41-43 | L38: 44-49 | M38: 50 | N38: 51-52 | O38: 53 | P38: 54 | Q38: 55-63 | R38: 64-65 | S38: 66-67 | T38: 68-73 | U38: 74-78 | V38: 79-80 | W38: 81-86 | X38: 87-88 | Y38: 89-95 | Z38: 96-102 | AA38: 103-105 | AB38: 106-112 | AC38: 113-119 | AD38: 120 | AE38: 121 | AF38: 122-128
B39: 1 | C39: 9 | D39: 1 | E39: 13 | F39: 2 | G39: 9 | H39: 1 | I39: 2 | J39: 2 | K39: 3 | L39: 6 | M39: 1 | N39: 2 | O39: 1 | P39: 1 | Q39: 9 | R39: 2 | S39: 2 | T39: 6 | U39: 5 | V39: 2 | W39: 6 | X39: 2 | Y39: 7 | Z39: 7 | AA39: 3 | AB39: 7 | AC39: 7 | AD39: 1 | AE39: 1 | AF39: 7
B40: N | C40: N | D40: A | E40: A | F40: N | G40: N | H40: A | I40: N | J40: N | K40: N | L40: N | M40: N | N40: A | O40: A | P40: A | Q40: N | R40: N | S40: N | T40: N | U40: A | V40: N | W40: N | X40: N | Y40: N | Z40: N | AA40: N | AB40: N | AC40: N | AD40: A | AE40: N | AF40: N
B41: O | C41: O | D41: F | E41: O | F41: O | G41: O | H41: F | I41: F | J41: F | K41: F | L41: F | M41: O | N41: F | O41: F | P41: F | Q41: F | R41: F | S41: OSIMO | T41: O | U41: O | V41: O | W41: O | X41: O | Y41: O | Z41: O | AA41: O | AB41: O | AC41: O | AD41: F | AE41: F | AF41: F
B42: 4 | C42: 422500009 | E42: 1500101001001 | F42: 77 | G42: 250000001 | H42: A | I42: 00 | J42: 00 | K42: 000 | L42: 000000 | M42: 9 | Q42: 422500009 | R42: 00 | S42: 00 | T42: 251201 | U42: FX1 | V42: 01 | W42: 000100 | X42: 01 | Y42: 0001300 | Z42: 0001300 | AA42: 055 | AB42: 0000715 | AC42: 0001300 | AE42: 1 | AF42: 0000000 | AG42: LIGNE A GENERER
A44: TYPE 4T | B44: Type d’enregistrement | C44: N° partenaire de santé + clé | D44: FILLER | E44: N° immatriculation assuré | F44: Clé N° immatriculation | G44: N° de facture | H44: Complément du type | I44: Séquence | J44: Filler | K44: Série (au sens du décret du 6/5/88) | L44: Transport lié à une hospitalisation | M44: Longue distance | N44: Filler | O44: Forfait type de forfait | P44: Prix unitaire du forfait non majoré | Q44: Quantité forfaits | R44: Quantité forfaits majoration de nuit | S44: Quantité forfaits majoration dimanche ou fériés | T44: Prix unitaire du kilomètre non réduit. | U44: SANS MAJORATION : Quantité <ou=150 km | V44: Quantité >150 km | W44: MAJORATION NUIT : Quantité <ou=150 km | X44: Quantité >150 km | Y44: MAJORATION DIMANCHE/FERIE : Quantité <ou=150 km | Z44: Quantité >150 km | AA44: SUPPLEMENT : Type supplément | AB44: Quantité | AC44: Montant | AD44: PEAGES ET VOIES D'EAU Quantité | AE44: Montant | AF44: Montant global des abattements | AG44: Montant global des majorations pour courte distance | AH44: Filler
B45: 1 | C45: 2-10 | D45: 11 | E45: 12-24 | F45: 25-26 | G45: 27-35 | H45: 36 | I45: 37-38 | J45: 39-45 | K45: 46 | L45: 47 | M45: 48 | N45: 49 | O45: 50 | P45: 51-56 | Q45: 57-58 | R45: 59-60 | S45: 61-62 | T45: 63-68 | U45: 69-72 | V45: 73-76 | W45: 77-80 | X45: 81-84 | Y45: 85-88 | Z45: 89-92 | AA45: 93 | AB45: 94-95 | AC45: 96-101 | AD45: 102-103, | AE45: 104-109 | AF45: 110-116 | AG45: 117-123 | AH45: 142-128
B46: 1 | C46: 9 | D46: 1 | E46: 13 | F46: 2 | G46: 9 | H46: 1 | I46: 2 | J46: 7 | K46: 1 | L46: 1 | M46: 1 | N46: 1 | O46: 1 | P46: 6 | Q46: 2 | R46: 2 | S46: 2 | T46: 6 | U46: 4 | V46: 4 | W46: 4 | X46: 4 | Y46: 4 | Z46: 4 | AA46: 1 | AB46: 2 | AC46: 6 | AD46: 2 | AE46: 6 | AF46: 7 | AG46: 7 | AH46: 5
B47: N | C47: N | D47: A | E47: A | F47: N | G47: N | H47: A | I47: N | J47: A | K47: N | L47: N | M47: N | N47: A | O47: N | P47: N | Q47: N | R47: N | S47: N | T47: N | U47: N | V47: N | W47: N | X47: N | Y47: N | Z47: N | AA47: N | AB47: N | AC47: N | AD47: N | AE47: N | AF47: N | AG47: N | AH47: A
B48: O | C48: O | D48: F | E48: O | F48: O | G48: O | H48: O | I48: F | J48: F | K48: O | L48: O | M48: O | N48: F | O48: O | P48: F | Q48: F | R48: F | S48: F | T48: F | U48: F | V48: F | W48: F | X48: F | Y48: F | Z48: F | AA48: F | AB48: F | AC48: F | AD48: F | AE48: F | AF48: F | AG48: F | AH48: F
...

Sheet CONVENTION CAS 2
A1: Table des matières | B1: CARACTERISTIQUES METIERS DU OU DES TRAJETS FACTURES
A3: SOCIETE DE TAXI DE N° AM : 422500009 SPECIALITE : 56 | D3: CARACTERISTIQUE PATIENT | G3: CARACTERISTIQUES FACTURE | I3: CARACTERISTIQUES TRAJETS | Z3: ASSURE | AG3: PRESCRIPTEUR
A4: N°CAS | B4: NOMBRE DE TRAJETS FACTURES | C4: TRAJET N° : | D4: NATURE D'ASSURANCE | E4: TAUX | F4: C2S ? : O/N | G4: REFUS TRANSPORT PARTAGE | H4: TIERS PAYANT | I4: LIEU DEPART | J4: LIEU ARRIVEE | K4: DATE / HEURE DEPART | L4: DATE / HEURE ARRIVEE | M4: N° IMMATRICULATION VEHICULE | N4: COMMUNE D'ADS | O4: DEPARTEMENT D'ADS | P4: ORGANISME LOCAL D'ADS | Q4: DISTANCE PARCOURUE | R4: CONTEXTE : J, N , F | S4: NOMBRE DE MALADES | T4: SUPPLEMENT FORFAITAIRE ? : O / N | U4: PEAGES ? : O / N | V4: TPMR ? : O / N | W4: TRAJET EN LIEN AVEC HOSPITALISATION ET RETOUR A VIDE ? : O/N | X4: SI T PARTAGE : TRAJET SEUL > X KM ? : O/N | Z4: NIR | AA4: DATE DE NAISSANCE | AB4: RANG | AC4: REGIME | AD4: CAISSE | AE4: CENTRE | AG4: N°AM | AH4: SPECIALITE | AI4: NN°RPPS
A5: ='LISTE DES CAS ANNEXE 30'!A5 -> CONVENTION CAS 2 | B5: ='LISTE DES CAS ANNEXE 30'!B5 -> 1 | C5: ='LISTE DES CAS ANNEXE 30'!C5 -> 1 | D5: ='LISTE DES CAS ANNEXE 30'!D5 -> MALADIE | E5: ='LISTE DES CAS ANNEXE 30'!E5 -> 0.55 | F5: ='LISTE DES CAS ANNEXE 30'!H5 -> NON | G5: ='LISTE DES CAS ANNEXE 30'!I5 -> Sans objet | H5: ='LISTE DES CAS ANNEXE 30'!J5 -> 05 - TP AMO SEUL | I5: ='LISTE DES CAS ANNEXE 30'!K5 -> 69-LYON | J5: ='LISTE DES CAS ANNEXE 30'!L5 -> 69-VILLEURBANNE | K5: ='LISTE DES CAS ANNEXE 30'!M5 -> 01/12/2025 à 10H00 | L5: ='LISTE DES CAS ANNEXE 30'!N5 -> 01/12/2025 à 10H11 | M5: ='LISTE DES CAS ANNEXE 30'!O5 -> EE-003-FF | ... X5: ='LISTE DES CAS ANNEXE 30'!Z5 -> Sans objet | Z5: 1500101001001 | AA5: 500101 | AB5: 1 | AC5: 01 | AD5: 422 | AE5: 0000 | AG5: 421000001 | AH5: 01 | AI5: 11111110118
A7: FACTURE B2 CORRESPONDANT
A9: TYPE 000 DEBUT FICHIER | B9: Type d’enregistrement | C9: Type d’émetteur | D9: Numéro d’émetteur | E9: FILLER | F9: Type de destinataire | G9: N° de destinataire | H9: Date de réception du flux sur le frontal | I9: Application | J9: Identification du fichier | K9: Date de création du fichier | L9: Norme | M9: Version de Norme | N9: FILLER | O9: FILLER | P9: FILLER | Q9: FILLER | R9: Longueur d’enregistrement | S9: FILLER | T9: Zone message
B10: 1-3 | C10: 4-5 | D10: 6-19 | E10: 20-25 | F10: 26-27 | G10: 28-41 | H10: 42-47 | I10: 48-49 | J10: 50-55 | K10: 56-61 | L10: 62-65 | M10: 66-67 | N10: 68 | O10: 69 | P10: 70-72 | Q10: 73-82 | R10: 83-85 | S10: 86-91 | T10: 92-128
B11: 3 | C11: 2 | D11: 14 | E11: 6 | F11: 2 | G11: 14 | H11: 6 | I11: 2 | J11: 6 | K11: 6 | L11: 4 | M11: 2 | N11: 1 | O11: 1 | P11: 3 | Q11: 10 | R11: 3 | S11: 6 | T11: 37
B12: N | C12: A | D12: N | E12: A | F12: A | G12: N | H12: A | I12: A | J12: A | K12: N | L12: A | M12: A | N12: A | O12: A | P12: A | Q12: A | R12: N | S12: A | T12: N
B13: O | C13: O | D13: O | E13: F | F13: O | G13: O | H13: O | I13: O | J13: O | K13: O | L13: O | M13: O | N13: F | O13: F | P13: F | Q13: F | R13: F | S13: F | T13: O
B14: 000 | C14: TP | D14: 00000422500009 | F14: CT | G14: 00000001000422 | H14: 251231 | I14: TR | J14: TESTB2 | K14: 251231 | L14: TA | M14: B2 | R14: 128
A16: TYPE 1 DEBUT LOT | B16: Type d’enregistrement | C16: N° partenaire de santé + clé | D16: Origine du fichier | E16: N° d’organisme destinataire | F16: N° de lot | G16: Catégorie | H16: Statut juridique | I16: Mode de fixation des tarifs | J16: Nom ou raison sociale du partenaire de santé | K16: Version de norme utilisée | L16: Date de création du lot | M16: Filler | N16: Code norme | O16: Top certification du lot | P16: Numéro de version de norme | Q16: Unité monétaire de facturation | R16: Grand régime de la caisse pivot ou de la caisse de paiement unique privés, ou pour les établissements publics et privés antérieurement sous DG | S16: N° de la caisse pivot ou de la caisse de paiement unique | T16: Indication de dispositif Caisse Centralisatrice des Paiements ou de dispositif Caisse de Paiement Unique | U16: FILLER
B17: 1 | C17: 2-10 | D17: 11-16 | E17: 17-19 | F17: 20-22 | G17: 23-25 | H17: 26-27 | I17: 28-29 | J17: 30-69 | K17: 70-71 | L17: 72-77 | M17: 78 | N17: 79-80 | O17: 81 | P17: 82-87 | Q17: 88 | R17: 89-90 | S17: 91-93 | T17: 94 | U17: 95-128
B18: 1 | C18: 9 | D18: 6 | E18: 3 | F18: 3 | G18: 3 | H18: 2 | I18: 2 | J18: 40 | K18: 2 | L18: 6 | M18: 1 | N18: 2 | O18: 1 | P18: 6 | Q18: 1 | R18: 2 | S18: 3 | T18: 1 | U18: 34
B19: N | C19: N | D19: A | E19: N | F19: N | G19: A | H19: A | I19: A | J19: A | K19: A | L19: N | M19: A | N19: A | O19: A | P19: N | Q19: A | R19: A | S19: A | T19: N | U19: A
B20: O | C20: O | D20: F | E20: O | F20: O | G20: F | H20: F | I20: F | J20: O | K20: O | L20: O | M20: F | N20: O | O20: F | P20: O | Q20: F | R20: F | S20: F | T20: F | U20: FILLER
B21: 1 | C21: 422500009 | E21: 422 | F21: 001 | J21: SIMULATEUR B2 NOUVELLE CONVENTION TAXI | K21: B2 | L21: 251231 | N21: TA | P21: 062007 | Q21: U
A23: TYPE 2 DEBUT FACTURE | B23: Type d’enregistrement | C23: N° partenaire de santé + clé | D23: FILLER | E23: N° immatriculation assuré | F23: Clé N° immatriculation | G23: N° facture | H23: Complément du type | I23: Marquage de la facture | J23: Indicateur de forçage de la tarification de la part AMO | K23: Nature d’opération | L23: Date de facturation | M23: Top éclatement des flux par le PS | N23: Type de facture | O23: Facture sécurisée sur un dispositif portable | P23: Code Grand Régime | Q23: N° Caisse gestionnaire | R23: N° Centre gestionnaire | S23: Nature de la pièce justificative des droits | T23: N° prescripteur + clé | U23: Date de prescription | V23: Régime de prestation de l’assuré | W23: Nature d’assurance | X23: Justification d’exonération ou de modulation du ticket modérateur | Y23: Date Maternité | Z23: Numéro accident du travail ou date d’accident de droit commun | AA23: Présence d’une CPS de remplaçant pour sécurisation de la facture | AB23: Date de naissance du bénéficiaire | AC23: Rang de naissance | AD23: Rang de bénéficiaire | AE23: N° d’adhérent | AF23: Spécialité de prescripteur | AG23: Destinataire du règlement | AH23: Type de contrat souscrit auprès d’un organisme complémentaire | AI23: N° d’organisme complémentaire
B24: 1 | C24: 2-10 | D24: 11 | E24: 12-24 | F24: 25-26 | G24: 27-35 | H24: 36 | I24: 37 | J24: 38 | K24: 39 | L24: 40-45 | M24: 46 | N24: 47 | O24: 48 | P24: 49-50 | Q24: 51-53 | R24: 54-57 | S24: 58 | T24: 59-67 | U24: 68-73 | V24: 74-76 | W24: 77-78 | X24: 79 | Y24: 80-85 | Z24: 86-94 | AA24: 95 | AB24: 96-101 | AC24: 102 | AD24: 103-104 | AE24: 105-112 | AF24: 113-114 | AG24: 115-116 | AH24: 117-118 | AI24: 119-128
B25: 1 | C25: 9 | D25: 1 | E25: 13 | F25: 2 | G25: 9 | H25: 1 | I25: 1 | J25: 1 | K25: 1 | L25: 6 | M25: 1 | N25: 1 | O25: 1 | P25: 2 | Q25: 3 | R25: 4 | S25: 1 | T25: 9 | U25: 6 | V25: 3 | W25: 2 | X25: 1 | Y25: 6 | Z25: 9 | AA25: 1 | AB25: 6 | AC25: 1 | AD25: 2 | AE25: 8 | AF25: 2 | AG25: 2 | AH25: 2 | AI25: 10
B26: N | C26: N | D26: A | E26: A | F26: N | G26: N | H26: A | I26: A | J26: A | K26: N | L26: N | M26: A | N26: A | O26: A | P26: N | Q26: N | R26: N | S26: N | T26: N | U26: N | V26: A | W26: N | X26: A | Y26: N | Z26: N | AA26: A | AB26: N | AC26: N | AD26: A | AE26: A | AF26: N | AG26: N | AH26: N | AI26: A
B27: O | C27: O | D27: F | E27: O | F27: O | G27: O | H27: F | I27: F | J27: F | K27: O | L27: O | M27: F | N27: F | O27: F | P27: O | Q27: O | R27: O | S27: O | T27: O | U27: O | V27: F | W27: F | X27: O | Y27: F | Z27: F | AA27: O | AB27: O | AC27: F | AD27: F | AE27: F | AF27: F | AG27: F | AH27: F | AI27: F
B28: 2 | C28: 422500009 | E28: 1500101001001 | F28: 77 | G28: 250000001 | H28: A | K28: 1 | L28: 251231 | P28: 01 | Q28: 422 | R28: 0000 | S28: 2 | T28: 421000001 | U28: 250701 | W28: 10 | X28: 0 | Y28: 000000 | Z28: 000000000 | AB28: 500101 | AC28: 1 | AF28: 01 | AG28: 05 | AH28: 00
A30: TYPE 2E RPPS PRESCRIPTEUR | B30: Type d’enregistrement | C30: N° partenaire de santé + clé | D30: FILLER | E30: N° immatriculation assuré | F30: Clé N° immatriculation | G30: N° de facture | H30: Complément de type | I30: Identfifiant RPPS du prescripteur | J30: N° de la structure dans laquelle le PS a exécuté l’acte | K30: FILLER
B31: 1 | C31: 2-10 | D31: 11 | E31: 12-24 | F31: 25-26 | G31: 27-35 | H31: 36 | I31: 37-47 | J31: 48-61 | K31: 62-128
B32: 1 | C32: 9 | D32: 1 | E32: 13 | F32: 2 | G32: 9 | H32: 1 | I32: 11 | J32: 14 | K32: 67
B33: N | C33: N | D33: A | E33: A | F33: N | G33: N | H33: A | I33: N | J33: N | K33: A
B34: O | C34: O | D34: F | E34: O | F34: O | G34: O | H34: F | I34: F | J34: F | K34: F
B35: 2 | C35: 422500009 | E35: 1500101001001 | F35: 77 | G35: 250000001 | H35: E | I35: 11111110118 | AG35: LIGNE A GENERER
A37: TYPE 4A COMPOSANTE FORFAIT | B37: Type d’enregistrement | C37: N° partenaire de santé + clé | D37: FILLER | E37: N° immatriculation assuré | F37: Clé N° immatriculation | G37: N° de facture | H37: Complément de type | I37: Séquence | J37: Mode de traitement | K37: Discipline de prestations (ex DMT) | L37: Date de la demande d’accord préalable ou date d’accord de prise en charge CMU. | M37: Code accord préalable | N37: Séquence de renouvellement | O37: Code Participation assuré | P37: Justification d’exonération du Ticket Modérateur au niveau de l’acte | Q37: N° exécutant + clé ayant effectué l’acte ou fourni le produit | R37: Zone tarif de l’exécutant | S37: Spécialité de l’exécutant | T37: Date de l’acte, de la délivrance du produit | U37: Code acte | V37: Quantité d'actes | W37: Coefficient | X37: Dénombrement | Y37: Prix unitaire | Z37: Base de remboursement | AA37: Taux applicable à la prestation- | AB37: Montant remboursable par l’organisme d’Assurance Maladie Obligatoire | AC37: Montant des honoraires ou de la dépense (dépassement compris ou après remise pour la norme FR) | AD37: Qualificatif de la dépense | AE37: Code lieu | AF37: Montant remboursable par l’organisme complémentaire
B38: 1 | C38: 2-10 | D38: 11 | E38: 12-24 | F38: 25-26 | G38: 27-35 | H38: 36 | I38: 37-38 | J38: 39-40 | K38: 41-43 | L38: 44-49 | M38: 50 | N38: 51-52 | O38: 53 | P38: 54 | Q38: 55-63 | R38: 64-65 | S38: 66-67 | T38: 68-73 | U38: 74-78 | V38: 79-80 | W38: 81-86 | X38: 87-88 | Y38: 89-95 | Z38: 96-102 | AA38: 103-105 | AB38: 106-112 | AC38: 113-119 | AD38: 120 | AE38: 121 | AF38: 122-128
B39: 1 | C39: 9 | D39: 1 | E39: 13 | F39: 2 | G39: 9 | H39: 1 | I39: 2 | J39: 2 | K39: 3 | L39: 6 | M39: 1 | N39: 2 | O39: 1 | P39: 1 | Q39: 9 | R39: 2 | S39: 2 | T39: 6 | U39: 5 | V39: 2 | W39: 6 | X39: 2 | Y39: 7 | Z39: 7 | AA39: 3 | AB39: 7 | AC39: 7 | AD39: 1 | AE39: 1 | AF39: 7
B40: N | C40: N | D40: A | E40: A | F40: N | G40: N | H40: A | I40: N | J40: N | K40: N | L40: N | M40: N | N40: A | O40: A | P40: A | Q40: N | R40: N | S40: N | T40: N | U40: A | V40: N | W40: N | X40: N | Y40: N | Z40: N | AA40: N | AB40: N | AC40: N | AD40: A | AE40: N | AF40: N
B41: O | C41: O | D41: F | E41: O | F41: O | G41: O | H41: F | I41: F | J41: F | K41: F | L41: F | M41: O | N41: F | O41: F | P41: F | Q41: F | R41: F | S41: OSIMO | T41: O | U41: O | V41: O | W41: O | X41: O | Y41: O | Z41: O | AA41: O | AB41: O | AC41: O | AD41: F | AE41: F | AF41: F
B42: 4 | C42: 422500009 | E42: 1500101001001 | F42: 77 | G42: 250000001 | H42: A | I42: 00 | J42: 00 | K42: 000 | L42: 000000 | M42: 9 | Q42: 422500009 | R42: 00 | S42: 00 | T42: 251201 | U42: FX2 | V42: 01 | W42: 000100 | X42: 01 | Y42: 0002800 | Z42: 0002800 | AA42: 055 | AB42: 0001540 | AC42: 0002800 | AE42: 1 | AF42: 0000000 | AG42: LIGNE A GENERER
A44: TYPE 4T | B44: Type d’enregistrement | C44: N° partenaire de santé + clé | D44: FILLER | E44: N° immatriculation assuré | F44: Clé N° immatriculation | G44: N° de facture | H44: Complément du type | I44: Séquence | J44: Filler | K44: Série (au sens du décret du 6/5/88) | L44: Transport lié à une hospitalisation | M44: Longue distance | N44: Filler | O44: Forfait type de forfait | P44: Prix unitaire du forfait non majoré | Q44: Quantité forfaits | R44: Quantité forfaits majoration de nuit | S44: Quantité forfaits majoration dimanche ou fériés | T44: Prix unitaire du kilomètre non réduit. | U44: SANS MAJORATION : Quantité <ou=150 km | V44: Quantité >150 km | W44: MAJORATION NUIT : Quantité <ou=150 km | X44: Quantité >150 km | Y44: MAJORATION DIMANCHE/FERIE : Quantité <ou=150 km | Z44: Quantité >150 km | AA44: SUPPLEMENT : Type supplément | AB44: Quantité | AC44: Montant | AD44: PEAGES ET VOIES D'EAU Quantité | AE44: Montant | AF44: Montant global des abattements | AG44: Montant global des majorations pour courte distance | AH44: Filler
B45: 1 | C45: 2-10 | D45: 11 | E45: 12-24 | F45: 25-26 | G45: 27-35 | H45: 36 | I45: 37-38 | J45: 39-45 | K45: 46 | L45: 47 | M45: 48 | N45: 49 | O45: 50 | P45: 51-56 | Q45: 57-58 | R45: 59-60 | S45: 61-62 | T45: 63-68 | U45: 69-72 | V45: 73-76 | W45: 77-80 | X45: 81-84 | Y45: 85-88 | Z45: 89-92 | AA45: 93 | AB45: 94-95 | AC45: 96-101 | AD45: 102-103, | AE45: 104-109 | AF45: 110-116 | AG45: 117-123 | AH45: 142-128
B46: 1 | C46: 9 | D46: 1 | E46: 13 | F46: 2 | G46: 9 | H46: 1 | I46: 2 | J46: 7 | K46: 1 | L46: 1 | M46: 1 | N46: 1 | O46: 1 | P46: 6 | Q46: 2 | R46: 2 | S46: 2 | T46: 6 | U46: 4 | V46: 4 | W46: 4 | X46: 4 | Y46: 4 | Z46: 4 | AA46: 1 | AB46: 2 | AC46: 6 | AD46: 2 | AE46: 6 | AF46: 7 | AG46: 7 | AH46: 5
B47: N | C47: N | D47: A | E47: A | F47: N | G47: N | H47: A | I47: N | J47: A | K47: N | L47: N | M47: N | N47: A | O47: N | P47: N | Q47: N | R47: N | S47: N | T47: N | U47: N | V47: N | W47: N | X47: N | Y47: N | Z47: N | AA47: N | AB47: N | AC47: N | AD47: N | AE47: N | AF47: N | AG47: N | AH47: A
B48: O | C48: O | D48: F | E48: O | F48: O | G48: O | H48: O | I48: F | J48: F | K48: O | L48: O | M48: O | N48: F | O48: O | P48: F | Q48: F | R48: F | S48: F | T48: F | U48: F | V48: F | W48: F | X48: F | Y48: F | Z48: F | AA48: F | AB48: F | AC48: F | AD48: F | AE48: F | AF48: F | AG48: F | AH48: F
...

Sheet CONVENTION CAS 3
A1: Table des matières | B1: CARACTERISTIQUES METIERS DU OU DES TRAJETS FACTURES
A3: SOCIETE DE TAXI DE N° AM : 422500009 SPECIALITE : 56 | D3: CARACTERISTIQUE PATIENT | G3: CARACTERISTIQUES FACTURE | I3: CARACTERISTIQUES TRAJETS | Z3: ASSURE | AG3: PRESCRIPTEUR
A4: N°CAS | B4: NOMBRE DE TRAJETS FACTURES | C4: TRAJET N° : | D4: NATURE D'ASSURANCE | E4: TAUX | F4: C2S ? : O/N | G4: REFUS TRANSPORT PARTAGE | H4: TIERS PAYANT | I4: LIEU DEPART | J4: LIEU ARRIVEE | K4: DATE / HEURE DEPART | L4: DATE / HEURE ARRIVEE | M4: N° IMMATRICULATION VEHICULE | N4: COMMUNE D'ADS | O4: DEPARTEMENT D'ADS | P4: ORGANISME LOCAL D'ADS | Q4: DISTANCE PARCOURUE | R4: CONTEXTE : J, N , F | S4: NOMBRE DE MALADES | T4: SUPPLEMENT FORFAITAIRE ? : O / N | U4: PEAGES ? : O / N | V4: TPMR ? : O / N | W4: TRAJET EN LIEN AVEC HOSPITALISATION ET RETOUR A VIDE ? : O/N | X4: SI T PARTAGE : TRAJET SEUL > X KM ? : O/N | Z4: NIR | AA4: DATE DE NAISSANCE | AB4: RANG | AC4: REGIME | AD4: CAISSE | AE4: CENTRE | AG4: N°AM | AH4: SPECIALITE | AI4: NN°RPPS
A5: ='LISTE DES CAS ANNEXE 30'!A7 -> CONVENTION CAS 3 | B5: ='LISTE DES CAS ANNEXE 30'!B7 -> 1 | C5: ='LISTE DES CAS ANNEXE 30'!C7 -> 1 | D5: ='LISTE DES CAS ANNEXE 30'!D7 -> MALADIE | E5: ='LISTE DES CAS ANNEXE 30'!E7 -> 0.55 | F5: ='LISTE DES CAS ANNEXE 30'!H7 -> NON | G5: ='LISTE DES CAS ANNEXE 30'!I7 -> Sans objet | H5: ='LISTE DES CAS ANNEXE 30'!J7 -> 05 - TP AMO SEUL | I5: ='LISTE DES CAS ANNEXE 30'!K7 -> 69-LYON | J5: ='LISTE DES CAS ANNEXE 30'!L7 -> 42-SAINT-ETIENNE | K5: ='LISTE DES CAS ANNEXE 30'!M7 -> 01/12/2025 à 10H00 | L5: ='LISTE DES CAS ANNEXE 30'!N7 -> 01/12/2025 à 11h15 | M5: ='LISTE DES CAS ANNEXE 30'!O7 -> EE-003-FF | ... X5: ='LISTE DES CAS ANNEXE 30'!Z7 -> Sans objet | Z5: 1500101001001 | AA5: 500101 | AB5: 1 | AC5: 01 | AD5: 422 | AE5: 0000 | AG5: 421000001 | AH5: 01 | AI5: 11111110118
A7: FACTURE B2 CORRESPONDANT
A9: TYPE 000 DEBUT FICHIER | B9: Type d’enregistrement | C9: Type d’émetteur | D9: Numéro d’émetteur | E9: FILLER | F9: Type de destinataire | G9: N° de destinataire | H9: Date de réception du flux sur le frontal | I9: Application | J9: Identification du fichier | K9: Date de création du fichier | L9: Norme | M9: Version de Norme | N9: FILLER | O9: FILLER | P9: FILLER | Q9: FILLER | R9: Longueur d’enregistrement | S9: FILLER | T9: Zone message
B10: 1-3 | C10: 4-5 | D10: 6-19 | E10: 20-25 | F10: 26-27 | G10: 28-41 | H10: 42-47 | I10: 48-49 | J10: 50-55 | K10: 56-61 | L10: 62-65 | M10: 66-67 | N10: 68 | O10: 69 | P10: 70-72 | Q10: 73-82 | R10: 83-85 | S10: 86-91 | T10: 92-128
B11: 3 | C11: 2 | D11: 14 | E11: 6 | F11: 2 | G11: 14 | H11: 6 | I11: 2 | J11: 6 | K11: 6 | L11: 4 | M11: 2 | N11: 1 | O11: 1 | P11: 3 | Q11: 10 | R11: 3 | S11: 6 | T11: 37
B12: N | C12: A | D12: N | E12: A | F12: A | G12: N | H12: A | I12: A | J12: A | K12: N | L12: A | M12: A | N12: A | O12: A | P12: A | Q12: A | R12: N | S12: A | T12: N
B13: O | C13: O | D13: O | E13: F | F13: O | G13: O | H13: O | I13: O | J13: O | K13: O | L13: O | M13: O | N13: F | O13: F | P13: F | Q13: F | R13: F | S13: F | T13: O
B14: 000 | C14: TP | D14: 00000422500009 | F14: CT | G14: 00000001000422 | H14: 251231 | I14: TR | J14: TESTB2 | K14: 251231 | L14: TA | M14: B2 | R14: 128
A16: TYPE 1 DEBUT LOT | B16: Type d’enregistrement | C16: N° partenaire de santé + clé | D16: Origine du fichier | E16: N° d’organisme destinataire | F16: N° de lot | G16: Catégorie | H16: Statut juridique | I16: Mode de fixation des tarifs | J16: Nom ou raison sociale du partenaire de santé | K16: Version de norme utilisée | L16: Date de création du lot | M16: Filler | N16: Code norme | O16: Top certification du lot | P16: Numéro de version de norme | Q16: Unité monétaire de facturation | R16: Grand régime de la caisse pivot ou de la caisse de paiement unique privés, ou pour les établissements publics et privés antérieurement sous DG | S16: N° de la caisse pivot ou de la caisse de paiement unique | T16: Indication de dispositif Caisse Centralisatrice des Paiements ou de dispositif Caisse de Paiement Unique | U16: FILLER
B17: 1 | C17: 2-10 | D17: 11-16 | E17: 17-19 | F17: 20-22 | G17: 23-25 | H17: 26-27 | I17: 28-29 | J17: 30-69 | K17: 70-71 | L17: 72-77 | M17: 78 | N17: 79-80 | O17: 81 | P17: 82-87 | Q17: 88 | R17: 89-90 | S17: 91-93 | T17: 94 | U17: 95-128
B18: 1 | C18: 9 | D18: 6 | E18: 3 | F18: 3 | G18: 3 | H18: 2 | I18: 2 | J18: 40 | K18: 2 | L18: 6 | M18: 1 | N18: 2 | O18: 1 | P18: 6 | Q18: 1 | R18: 2 | S18: 3 | T18: 1 | U18: 34
B19: N | C19: N | D19: A | E19: N | F19: N | G19: A | H19: A | I19: A | J19: A | K19: A | L19: N | M19: A | N19: A | O19: A | P19: N | Q19: A | R19: A | S19: A | T19: N | U19: A
B20: O | C20: O | D20: F | E20: O | F20: O | G20: F | H20: F | I20: F | J20: O | K20: O | L20: O | M20: F | N20: O | O20: F | P20: O | Q20: F | R20: F | S20: F | T20: F | U20: FILLER
B21: 1 | C21: 422500009 | E21: 422 | F21: 001 | J21: SIMULATEUR B2 NOUVELLE CONVENTION TAXI | K21: B2 | L21: 251231 | N21: TA | P21: 062007 | Q21: U
A23: TYPE 2 DEBUT FACTURE | B23: Type d’enregistrement | C23: N° partenaire de santé + clé | D23: FILLER | E23: N° immatriculation assuré | F23: Clé N° immatriculation | G23: N° facture | H23: Complément du type | I23: Marquage de la facture | J23: Indicateur de forçage de la tarification de la part AMO | K23: Nature d’opération | L23: Date de facturation | M23: Top éclatement des flux par le PS | N23: Type de facture | O23: Facture sécurisée sur un dispositif portable | P23: Code Grand Régime | Q23: N° Caisse gestionnaire | R23: N° Centre gestionnaire | S23: Nature de la pièce justificative des droits | T23: N° prescripteur + clé | U23: Date de prescription | V23: Régime de prestation de l’assuré | W23: Nature d’assurance | X23: Justification d’exonération ou de modulation du ticket modérateur | Y23: Date Maternité | Z23: Numéro accident du travail ou date d’accident de droit commun | AA23: Présence d’une CPS de remplaçant pour sécurisation de la facture | AB23: Date de naissance du bénéficiaire | AC23: Rang de naissance | AD23: Rang de bénéficiaire | AE23: N° d’adhérent | AF23: Spécialité de prescripteur | AG23: Destinataire du règlement | AH23: Type de contrat souscrit auprès d’un organisme complémentaire | AI23: N° d’organisme complémentaire
B24: 1 | C24: 2-10 | D24: 11 | E24: 12-24 | F24: 25-26 | G24: 27-35 | H24: 36 | I24: 37 | J24: 38 | K24: 39 | L24: 40-45 | M24: 46 | N24: 47 | O24: 48 | P24: 49-50 | Q24: 51-53 | R24: 54-57 | S24: 58 | T24: 59-67 | U24: 68-73 | V24: 74-76 | W24: 77-78 | X24: 79 | Y24: 80-85 | Z24: 86-94 | AA24: 95 | AB24: 96-101 | AC24: 102 | AD24: 103-104 | AE24: 105-112 | AF24: 113-114 | AG24: 115-116 | AH24: 117-118 | AI24: 119-128
B25: 1 | C25: 9 | D25: 1 | E25: 13 | F25: 2 | G25: 9 | H25: 1 | I25: 1 | J25: 1 | K25: 1 | L25: 6 | M25: 1 | N25: 1 | O25: 1 | P25: 2 | Q25: 3 | R25: 4 | S25: 1 | T25: 9 | U25: 6 | V25: 3 | W25: 2 | X25: 1 | Y25: 6 | Z25: 9 | AA25: 1 | AB25: 6 | AC25: 1 | AD25: 2 | AE25: 8 | AF25: 2 | AG25: 2 | AH25: 2 | AI25: 10
B26: N | C26: N | D26: A | E26: A | F26: N | G26: N | H26: A | I26: A | J26: A | K26: N | L26: N | M26: A | N26: A | O26: A | P26: N | Q26: N | R26: N | S26: N | T26: N | U26: N | V26: A | W26: N | X26: A | Y26: N | Z26: N | AA26: A | AB26: N | AC26: N | AD26: A | AE26: A | AF26: N | AG26: N | AH26: N | AI26: A
B27: O | C27: O | D27: F | E27: O | F27: O | G27: O | H27: F | I27: F | J27: F | K27: O | L27: O | M27: F | N27: F | O27: F | P27: O | Q27: O | R27: O | S27: O | T27: O | U27: O | V27: F | W27: F | X27: O | Y27: F | Z27: F | AA27: O | AB27: O | AC27: F | AD27: F | AE27: F | AF27: F | AG27: F | AH27: F | AI27: F
B28: 2 | C28: 422500009 | E28: 1500101001001 | F28: 77 | G28: 250000001 | H28: A | K28: 1 | L28: 251231 | P28: 01 | Q28: 422 | R28: 0000 | S28: 2 | T28: 421000001 | U28: 250701 | W28: 10 | X28: 0 | Y28: 000000 | Z28: 000000000 | AB28: 500101 | AC28: 1 | AF28: 01 | AG28: 05 | AH28: 00
A30: TYPE 2E RPPS PRESCRIPTEUR | B30: Type d’enregistrement | C30: N° partenaire de santé + clé | D30: FILLER | E30: N° immatriculation assuré | F30: Clé N° immatriculation | G30: N° de facture | H30: Complément de type | I30: Identfifiant RPPS du prescripteur | J30: N° de la structure dans laquelle le PS a exécuté l’acte | K30: FILLER
B31: 1 | C31: 2-10 | D31: 11 | E31: 12-24 | F31: 25-26 | G31: 27-35 | H31: 36 | I31: 37-47 | J31: 48-61 | K31: 62-128
B32: 1 | C32: 9 | D32: 1 | E32: 13 | F32: 2 | G32: 9 | H32: 1 | I32: 11 | J32: 14 | K32: 67
B33: N | C33: N | D33: A | E33: A | F33: N | G33: N | H33: A | I33: N | J33: N | K33: A
B34: O | C34: O | D34: F | E34: O | F34: O | G34: O | H34: F | I34: F | J34: F | K34: F
B35: 2 | C35: 422500009 | E35: 1500101001001 | F35: 77 | G35: 250000001 | H35: E | I35: 11111110118 | AG35: LIGNE A GENERER
A37: TYPE 4A COMPOSANTE FORFAIT | B37: Type d’enregistrement | C37: N° partenaire de santé + clé | D37: FILLER | E37: N° immatriculation assuré | F37: Clé N° immatriculation | G37: N° de facture | H37: Complément de type | I37: Séquence | J37: Mode de traitement | K37: Discipline de prestations (ex DMT) | L37: Date de la demande d’accord préalable ou date d’accord de prise en charge CMU. | M37: Code accord préalable | N37: Séquence de renouvellement | O37: Code Participation assuré | P37: Justification d’exonération du Ticket Modérateur au niveau de l’acte | Q37: N° exécutant + clé ayant effectué l’acte ou fourni le produit | R37: Zone tarif de l’exécutant | S37: Spécialité de l’exécutant | T37: Date de l’acte, de la délivrance du produit | U37: Code acte | V37: Quantité d'actes | W37: Coefficient | X37: Dénombrement | Y37: Prix unitaire | Z37: Base de remboursement | AA37: Taux applicable à la prestation- | AB37: Montant remboursable par l’organisme d’Assurance Maladie Obligatoire | AC37: Montant des honoraires ou de la dépense (dépassement compris ou après remise pour la norme FR) | AD37: Qualificatif de la dépense | AE37: Code lieu | AF37: Montant remboursable par l’organisme complémentaire
B38: 1 | C38: 2-10 | D38: 11 | E38: 12-24 | F38: 25-26 | G38: 27-35 | H38: 36 | I38: 37-38 | J38: 39-40 | K38: 41-43 | L38: 44-49 | M38: 50 | N38: 51-52 | O38: 53 | P38: 54 | Q38: 55-63 | R38: 64-65 | S38: 66-67 | T38: 68-73 | U38: 74-78 | V38: 79-80 | W38: 81-86 | X38: 87-88 | Y38: 89-95 | Z38: 96-102 | AA38: 103-105 | AB38: 106-112 | AC38: 113-119 | AD38: 120 | AE38: 121 | AF38: 122-128
B39: 1 | C39: 9 | D39: 1 | E39: 13 | F39: 2 | G39: 9 | H39: 1 | I39: 2 | J39: 2 | K39: 3 | L39: 6 | M39: 1 | N39: 2 | O39: 1 | P39: 1 | Q39: 9 | R39: 2 | S39: 2 | T39: 6 | U39: 5 | V39: 2 | W39: 6 | X39: 2 | Y39: 7 | Z39: 7 | AA39: 3 | AB39: 7 | AC39: 7 | AD39: 1 | AE39: 1 | AF39: 7
B40: N | C40: N | D40: A | E40: A | F40: N | G40: N | H40: A | I40: N | J40: N | K40: N | L40: N | M40: N | N40: A | O40: A | P40: A | Q40: N | R40: N | S40: N | T40: N | U40: A | V40: N | W40: N | X40: N | Y40: N | Z40: N | AA40: N | AB40: N | AC40: N | AD40: A | AE40: N | AF40: N
B41: O | C41: O | D41: F | E41: O | F41: O | G41: O | H41: F | I41: F | J41: F | K41: F | L41: F | M41: O | N41: F | O41: F | P41: F | Q41: F | R41: F | S41: OSIMO | T41: O | U41: O | V41: O | W41: O | X41: O | Y41: O | Z41: O | AA41: O | AB41: O | AC41: O | AD41: F | AE41: F | AF41: F
B42: 4 | C42: 422500009 | E42: 1500101001001 | F42: 77 | G42: 250000001 | H42: A | I42: 00 | J42: 00 | K42: 000 | L42: 000000 | M42: 9 | Q42: 422500009 | R42: 00 | S42: 00 | T42: 251201 | U42: FX2 | V42: 01 | W42: 000100 | X42: 01 | Y42: 0002800 | Z42: 0002800 | AA42: 055 | AB42: 0001540 | AC42: 0002800 | AE42: 1 | AF42: 0000000 | AG42: LIGNE A GENERER
A44: TYPE 4T | B44: Type d’enregistrement | C44: N° partenaire de santé + clé | D44: FILLER | E44: N° immatriculation assuré | F44: Clé N° immatriculation | G44: N° de facture | H44: Complément du type | I44: Séquence | J44: Filler | K44: Série (au sens du décret du 6/5/88) | L44: Transport lié à une hospitalisation | M44: Longue distance | N44: Filler | O44: Forfait type de forfait | P44: Prix unitaire du forfait non majoré | Q44: Quantité forfaits | R44: Quantité forfaits majoration de nuit | S44: Quantité forfaits majoration dimanche ou fériés | T44: Prix unitaire du kilomètre non réduit. | U44: SANS MAJORATION : Quantité <ou=150 km | V44: Quantité >150 km | W44: MAJORATION NUIT : Quantité <ou=150 km | X44: Quantité >150 km | Y44: MAJORATION DIMANCHE/FERIE : Quantité <ou=150 km | Z44: Quantité >150 km | AA44: SUPPLEMENT : Type supplément | AB44: Quantité | AC44: Montant | AD44: PEAGES ET VOIES D'EAU Quantité | AE44: Montant | AF44: Montant global des abattements | AG44: Montant global des majorations pour courte distance | AH44: Filler
B45: 1 | C45: 2-10 | D45: 11 | E45: 12-24 | F45: 25-26 | G45: 27-35 | H45: 36 | I45: 37-38 | J45: 39-45 | K45: 46 | L45: 47 | M45: 48 | N45: 49 | O45: 50 | P45: 51-56 | Q45: 57-58 | R45: 59-60 | S45: 61-62 | T45: 63-68 | U45: 69-72 | V45: 73-76 | W45: 77-80 | X45: 81-84 | Y45: 85-88 | Z45: 89-92 | AA45: 93 | AB45: 94-95 | AC45: 96-101 | AD45: 102-103, | AE45: 104-109 | AF45: 110-116 | AG45: 117-123 | AH45: 142-128
B46: 1 | C46: 9 | D46: 1 | E46: 13 | F46: 2 | G46: 9 | H46: 1 | I46: 2 | J46: 7 | K46: 1 | L46: 1 | M46: 1 | N46: 1 | O46: 1 | P46: 6 | Q46: 2 | R46: 2 | S46: 2 | T46: 6 | U46: 4 | V46: 4 | W46: 4 | X46: 4 | Y46: 4 | Z46: 4 | AA46: 1 | AB46: 2 | AC46: 6 | AD46: 2 | AE46: 6 | AF46: 7 | AG46: 7 | AH46: 5
